2013_01_29 16:05:23 :<ErrorMessage  body=None extendedData=['Traceback (most recent call last):\n', '  File "H:/ProjectGit/OASystem\\pyamf\\remoting\\amf3.py", line 188, in __call__\n    return self._getBody(amf_request, ro_request, **kwargs)\n', '  File "H:/ProjectGit/OASystem\\pyamf\\remoting\\amf3.py", line 125, in _getBody\n    return self._processRemotingMessage(amf_request, ro_request, **kwargs)\n', '  File "H:/ProjectGit/OASystem\\pyamf\\remoting\\amf3.py", line 171, in _processRemotingMessage\n    *ro_request.body, **kwargs)\n', '  File "H:/ProjectGit/OASystem\\pyamf\\remoting\\gateway\\__init__.py", line 513, in callServiceRequest\n    return service_request(*args)\n', '  File "H:/ProjectGit/OASystem\\pyamf\\remoting\\gateway\\__init__.py", line 233, in __call__\n    return self.service(self.method, args)\n', '  File "H:/ProjectGit/OASystem\\pyamf\\remoting\\gateway\\__init__.py", line 133, in __call__\n    return func(*params)\n', '  File "C:\\Python27\\lib\\site-packages\\django\\contrib\\auth\\decorators.py", line 23, in _wrapped_view\n    return view_func(request, *args, **kwargs)\n', 'TypeError: getUser() takes exactly 1 argument (2 given)\n'] rootCause=TypeError('getUser() takes exactly 1 argument (2 given)',) timestamp=1359446723 destination=None faultDetail=u'[\'Traceback (most recent call last):\\n\', \'  File "H:/ProjectGit/OASystem\\\\pyamf\\\\remoting\\\\amf3.py", line 188, in __call__\\n    return self._getBody(amf_request, ro_request, **kwargs)\\n\', \'  File "H:/ProjectGit/OASystem\\\\pyamf\\\\remoting\\\\amf3.py", line 125, in _getBody\\n    return self._processRemotingMessage(amf_request, ro_request, **kwargs)\\n\', \'  File "H:/ProjectGit/OASystem\\\\pyamf\\\\remoting\\\\amf3.py", line 171, in _processRemotingMessage\\n    *ro_request.body, **kwargs)\\n\', \'  File "H:/ProjectGit/OASystem\\\\pyamf\\\\remoting\\\\gateway\\\\__init__.py", line 513, in callServiceRequest\\n    return service_request(*args)\\n\', \'  File "H:/ProjectGit/OASystem\\\\pyamf\\\\remoting\\\\gateway\\\\__init__.py", line 233, in __call__\\n    return self.service(self.method, args)\\n\', \'  File "H:/ProjectGit/OASystem\\\\pyamf\\\\remoting\\\\gateway\\\\__init__.py", line 133, in __call__\\n    return func(*params)\\n\', \'  File "C:\\\\Python27\\\\lib\\\\site-packages\\\\django\\\\contrib\\\\auth\\\\decorators.py", line 23, in _wrapped_view\\n    return view_func(request, *args, **kwargs)\\n\', \'TypeError: getUser() takes exactly 1 argument (2 given)\\n\']' clientId='583f7220-80eb-421f-afb9-4f3a783aa0f8' headers={} faultCode='TypeError' timeToLive=None messageId='94f24ce7-ca88-435a-baac-a43138bf4703' faultString=u'getUser() takes exactly 1 argument (2 given)' correlationId=u'3848824C-7E44-4C2C-A2B8-8556C9D7A718' />
2013_01_29 16:05:24 :<ErrorMessage  body=None extendedData=['Traceback (most recent call last):\n', '  File "H:/ProjectGit/OASystem\\pyamf\\remoting\\amf3.py", line 188, in __call__\n    return self._getBody(amf_request, ro_request, **kwargs)\n', '  File "H:/ProjectGit/OASystem\\pyamf\\remoting\\amf3.py", line 125, in _getBody\n    return self._processRemotingMessage(amf_request, ro_request, **kwargs)\n', '  File "H:/ProjectGit/OASystem\\pyamf\\remoting\\amf3.py", line 171, in _processRemotingMessage\n    *ro_request.body, **kwargs)\n', '  File "H:/ProjectGit/OASystem\\pyamf\\remoting\\gateway\\__init__.py", line 513, in callServiceRequest\n    return service_request(*args)\n', '  File "H:/ProjectGit/OASystem\\pyamf\\remoting\\gateway\\__init__.py", line 233, in __call__\n    return self.service(self.method, args)\n', '  File "H:/ProjectGit/OASystem\\pyamf\\remoting\\gateway\\__init__.py", line 133, in __call__\n    return func(*params)\n', '  File "C:\\Python27\\lib\\site-packages\\django\\contrib\\auth\\decorators.py", line 23, in _wrapped_view\n    return view_func(request, *args, **kwargs)\n', 'TypeError: getAllUser() takes exactly 1 argument (2 given)\n'] rootCause=TypeError('getAllUser() takes exactly 1 argument (2 given)',) timestamp=1359446724 destination=None faultDetail=u'[\'Traceback (most recent call last):\\n\', \'  File "H:/ProjectGit/OASystem\\\\pyamf\\\\remoting\\\\amf3.py", line 188, in __call__\\n    return self._getBody(amf_request, ro_request, **kwargs)\\n\', \'  File "H:/ProjectGit/OASystem\\\\pyamf\\\\remoting\\\\amf3.py", line 125, in _getBody\\n    return self._processRemotingMessage(amf_request, ro_request, **kwargs)\\n\', \'  File "H:/ProjectGit/OASystem\\\\pyamf\\\\remoting\\\\amf3.py", line 171, in _processRemotingMessage\\n    *ro_request.body, **kwargs)\\n\', \'  File "H:/ProjectGit/OASystem\\\\pyamf\\\\remoting\\\\gateway\\\\__init__.py", line 513, in callServiceRequest\\n    return service_request(*args)\\n\', \'  File "H:/ProjectGit/OASystem\\\\pyamf\\\\remoting\\\\gateway\\\\__init__.py", line 233, in __call__\\n    return self.service(self.method, args)\\n\', \'  File "H:/ProjectGit/OASystem\\\\pyamf\\\\remoting\\\\gateway\\\\__init__.py", line 133, in __call__\\n    return func(*params)\\n\', \'  File "C:\\\\Python27\\\\lib\\\\site-packages\\\\django\\\\contrib\\\\auth\\\\decorators.py", line 23, in _wrapped_view\\n    return view_func(request, *args, **kwargs)\\n\', \'TypeError: getAllUser() takes exactly 1 argument (2 given)\\n\']' clientId='39504596-d9cb-410c-a869-560f1bc0c39c' headers={} faultCode='TypeError' timeToLive=None messageId='74fb50fe-517c-4d8a-abbb-2fbd921ad154' faultString=u'getAllUser() takes exactly 1 argument (2 given)' correlationId=u'040B985F-AEB6-73C0-01A7-8556C9D795A2' />
2013_01_29 16:05:24 :<ErrorMessage  body=None extendedData=['Traceback (most recent call last):\n', '  File "H:/ProjectGit/OASystem\\pyamf\\remoting\\amf3.py", line 188, in __call__\n    return self._getBody(amf_request, ro_request, **kwargs)\n', '  File "H:/ProjectGit/OASystem\\pyamf\\remoting\\amf3.py", line 125, in _getBody\n    return self._processRemotingMessage(amf_request, ro_request, **kwargs)\n', '  File "H:/ProjectGit/OASystem\\pyamf\\remoting\\amf3.py", line 171, in _processRemotingMessage\n    *ro_request.body, **kwargs)\n', '  File "H:/ProjectGit/OASystem\\pyamf\\remoting\\gateway\\__init__.py", line 513, in callServiceRequest\n    return service_request(*args)\n', '  File "H:/ProjectGit/OASystem\\pyamf\\remoting\\gateway\\__init__.py", line 233, in __call__\n    return self.service(self.method, args)\n', '  File "H:/ProjectGit/OASystem\\pyamf\\remoting\\gateway\\__init__.py", line 133, in __call__\n    return func(*params)\n', '  File "C:\\Python27\\lib\\site-packages\\django\\contrib\\auth\\decorators.py", line 23, in _wrapped_view\n    return view_func(request, *args, **kwargs)\n', 'TypeError: getAllUser() takes exactly 1 argument (2 given)\n'] rootCause=TypeError('getAllUser() takes exactly 1 argument (2 given)',) timestamp=1359446724 destination=None faultDetail=u'[\'Traceback (most recent call last):\\n\', \'  File "H:/ProjectGit/OASystem\\\\pyamf\\\\remoting\\\\amf3.py", line 188, in __call__\\n    return self._getBody(amf_request, ro_request, **kwargs)\\n\', \'  File "H:/ProjectGit/OASystem\\\\pyamf\\\\remoting\\\\amf3.py", line 125, in _getBody\\n    return self._processRemotingMessage(amf_request, ro_request, **kwargs)\\n\', \'  File "H:/ProjectGit/OASystem\\\\pyamf\\\\remoting\\\\amf3.py", line 171, in _processRemotingMessage\\n    *ro_request.body, **kwargs)\\n\', \'  File "H:/ProjectGit/OASystem\\\\pyamf\\\\remoting\\\\gateway\\\\__init__.py", line 513, in callServiceRequest\\n    return service_request(*args)\\n\', \'  File "H:/ProjectGit/OASystem\\\\pyamf\\\\remoting\\\\gateway\\\\__init__.py", line 233, in __call__\\n    return self.service(self.method, args)\\n\', \'  File "H:/ProjectGit/OASystem\\\\pyamf\\\\remoting\\\\gateway\\\\__init__.py", line 133, in __call__\\n    return func(*params)\\n\', \'  File "C:\\\\Python27\\\\lib\\\\site-packages\\\\django\\\\contrib\\\\auth\\\\decorators.py", line 23, in _wrapped_view\\n    return view_func(request, *args, **kwargs)\\n\', \'TypeError: getAllUser() takes exactly 1 argument (2 given)\\n\']' clientId='babee5e2-3105-4fb4-92df-a1af323205ce' headers={} faultCode='TypeError' timeToLive=None messageId='6df80ed1-2851-4cdd-8b1c-6cab36ded10e' faultString=u'getAllUser() takes exactly 1 argument (2 given)' correlationId=u'673BB6C9-1384-817F-A376-8556C9D74B4A' />
2013_01_29 16:05:24 :<ErrorMessage  body=None extendedData=['Traceback (most recent call last):\n', '  File "H:/ProjectGit/OASystem\\pyamf\\remoting\\amf3.py", line 188, in __call__\n    return self._getBody(amf_request, ro_request, **kwargs)\n', '  File "H:/ProjectGit/OASystem\\pyamf\\remoting\\amf3.py", line 125, in _getBody\n    return self._processRemotingMessage(amf_request, ro_request, **kwargs)\n', '  File "H:/ProjectGit/OASystem\\pyamf\\remoting\\amf3.py", line 171, in _processRemotingMessage\n    *ro_request.body, **kwargs)\n', '  File "H:/ProjectGit/OASystem\\pyamf\\remoting\\gateway\\__init__.py", line 513, in callServiceRequest\n    return service_request(*args)\n', '  File "H:/ProjectGit/OASystem\\pyamf\\remoting\\gateway\\__init__.py", line 233, in __call__\n    return self.service(self.method, args)\n', '  File "H:/ProjectGit/OASystem\\pyamf\\remoting\\gateway\\__init__.py", line 133, in __call__\n    return func(*params)\n', '  File "C:\\Python27\\lib\\site-packages\\django\\contrib\\auth\\decorators.py", line 23, in _wrapped_view\n    return view_func(request, *args, **kwargs)\n', 'TypeError: userhaschange() takes exactly 1 argument (2 given)\n'] rootCause=TypeError('userhaschange() takes exactly 1 argument (2 given)',) timestamp=1359446724 destination=None faultDetail=u'[\'Traceback (most recent call last):\\n\', \'  File "H:/ProjectGit/OASystem\\\\pyamf\\\\remoting\\\\amf3.py", line 188, in __call__\\n    return self._getBody(amf_request, ro_request, **kwargs)\\n\', \'  File "H:/ProjectGit/OASystem\\\\pyamf\\\\remoting\\\\amf3.py", line 125, in _getBody\\n    return self._processRemotingMessage(amf_request, ro_request, **kwargs)\\n\', \'  File "H:/ProjectGit/OASystem\\\\pyamf\\\\remoting\\\\amf3.py", line 171, in _processRemotingMessage\\n    *ro_request.body, **kwargs)\\n\', \'  File "H:/ProjectGit/OASystem\\\\pyamf\\\\remoting\\\\gateway\\\\__init__.py", line 513, in callServiceRequest\\n    return service_request(*args)\\n\', \'  File "H:/ProjectGit/OASystem\\\\pyamf\\\\remoting\\\\gateway\\\\__init__.py", line 233, in __call__\\n    return self.service(self.method, args)\\n\', \'  File "H:/ProjectGit/OASystem\\\\pyamf\\\\remoting\\\\gateway\\\\__init__.py", line 133, in __call__\\n    return func(*params)\\n\', \'  File "C:\\\\Python27\\\\lib\\\\site-packages\\\\django\\\\contrib\\\\auth\\\\decorators.py", line 23, in _wrapped_view\\n    return view_func(request, *args, **kwargs)\\n\', \'TypeError: userhaschange() takes exactly 1 argument (2 given)\\n\']' clientId='6a1653f6-ada7-486d-aa77-dcdebbbc3cc9' headers={} faultCode='TypeError' timeToLive=None messageId='7cd95ea5-cdd6-4640-9b4b-aa033697c15d' faultString=u'userhaschange() takes exactly 1 argument (2 given)' correlationId=u'2BAB89B4-E23B-A694-EB60-8556C9D73BEB' />
2013_01_29 16:06:11 :<ErrorMessage  body=None extendedData=['Traceback (most recent call last):\n', '  File "H:/ProjectGit/OASystem\\pyamf\\remoting\\amf3.py", line 188, in __call__\n    return self._getBody(amf_request, ro_request, **kwargs)\n', '  File "H:/ProjectGit/OASystem\\pyamf\\remoting\\amf3.py", line 125, in _getBody\n    return self._processRemotingMessage(amf_request, ro_request, **kwargs)\n', '  File "H:/ProjectGit/OASystem\\pyamf\\remoting\\amf3.py", line 171, in _processRemotingMessage\n    *ro_request.body, **kwargs)\n', '  File "H:/ProjectGit/OASystem\\pyamf\\remoting\\gateway\\__init__.py", line 513, in callServiceRequest\n    return service_request(*args)\n', '  File "H:/ProjectGit/OASystem\\pyamf\\remoting\\gateway\\__init__.py", line 233, in __call__\n    return self.service(self.method, args)\n', '  File "H:/ProjectGit/OASystem\\pyamf\\remoting\\gateway\\__init__.py", line 133, in __call__\n    return func(*params)\n', '  File "C:\\Python27\\lib\\site-packages\\django\\contrib\\auth\\decorators.py", line 23, in _wrapped_view\n    return view_func(request, *args, **kwargs)\n', 'TypeError: getUser() takes exactly 1 argument (2 given)\n'] rootCause=TypeError('getUser() takes exactly 1 argument (2 given)',) timestamp=1359446771 destination=None faultDetail=u'[\'Traceback (most recent call last):\\n\', \'  File "H:/ProjectGit/OASystem\\\\pyamf\\\\remoting\\\\amf3.py", line 188, in __call__\\n    return self._getBody(amf_request, ro_request, **kwargs)\\n\', \'  File "H:/ProjectGit/OASystem\\\\pyamf\\\\remoting\\\\amf3.py", line 125, in _getBody\\n    return self._processRemotingMessage(amf_request, ro_request, **kwargs)\\n\', \'  File "H:/ProjectGit/OASystem\\\\pyamf\\\\remoting\\\\amf3.py", line 171, in _processRemotingMessage\\n    *ro_request.body, **kwargs)\\n\', \'  File "H:/ProjectGit/OASystem\\\\pyamf\\\\remoting\\\\gateway\\\\__init__.py", line 513, in callServiceRequest\\n    return service_request(*args)\\n\', \'  File "H:/ProjectGit/OASystem\\\\pyamf\\\\remoting\\\\gateway\\\\__init__.py", line 233, in __call__\\n    return self.service(self.method, args)\\n\', \'  File "H:/ProjectGit/OASystem\\\\pyamf\\\\remoting\\\\gateway\\\\__init__.py", line 133, in __call__\\n    return func(*params)\\n\', \'  File "C:\\\\Python27\\\\lib\\\\site-packages\\\\django\\\\contrib\\\\auth\\\\decorators.py", line 23, in _wrapped_view\\n    return view_func(request, *args, **kwargs)\\n\', \'TypeError: getUser() takes exactly 1 argument (2 given)\\n\']' clientId='7618d46a-5998-4990-a2d1-60279ba576f5' headers={} faultCode='TypeError' timeToLive=None messageId='8dcd82d3-d430-4387-92ae-74c5ae0c55e1' faultString=u'getUser() takes exactly 1 argument (2 given)' correlationId=u'36C3F255-6979-6365-C123-855787897865' />
2013_01_29 16:06:12 :<ErrorMessage  body=None extendedData=['Traceback (most recent call last):\n', '  File "H:/ProjectGit/OASystem\\pyamf\\remoting\\amf3.py", line 188, in __call__\n    return self._getBody(amf_request, ro_request, **kwargs)\n', '  File "H:/ProjectGit/OASystem\\pyamf\\remoting\\amf3.py", line 125, in _getBody\n    return self._processRemotingMessage(amf_request, ro_request, **kwargs)\n', '  File "H:/ProjectGit/OASystem\\pyamf\\remoting\\amf3.py", line 171, in _processRemotingMessage\n    *ro_request.body, **kwargs)\n', '  File "H:/ProjectGit/OASystem\\pyamf\\remoting\\gateway\\__init__.py", line 513, in callServiceRequest\n    return service_request(*args)\n', '  File "H:/ProjectGit/OASystem\\pyamf\\remoting\\gateway\\__init__.py", line 233, in __call__\n    return self.service(self.method, args)\n', '  File "H:/ProjectGit/OASystem\\pyamf\\remoting\\gateway\\__init__.py", line 133, in __call__\n    return func(*params)\n', '  File "C:\\Python27\\lib\\site-packages\\django\\contrib\\auth\\decorators.py", line 23, in _wrapped_view\n    return view_func(request, *args, **kwargs)\n', 'TypeError: getAllUser() takes exactly 1 argument (2 given)\n'] rootCause=TypeError('getAllUser() takes exactly 1 argument (2 given)',) timestamp=1359446772 destination=None faultDetail=u'[\'Traceback (most recent call last):\\n\', \'  File "H:/ProjectGit/OASystem\\\\pyamf\\\\remoting\\\\amf3.py", line 188, in __call__\\n    return self._getBody(amf_request, ro_request, **kwargs)\\n\', \'  File "H:/ProjectGit/OASystem\\\\pyamf\\\\remoting\\\\amf3.py", line 125, in _getBody\\n    return self._processRemotingMessage(amf_request, ro_request, **kwargs)\\n\', \'  File "H:/ProjectGit/OASystem\\\\pyamf\\\\remoting\\\\amf3.py", line 171, in _processRemotingMessage\\n    *ro_request.body, **kwargs)\\n\', \'  File "H:/ProjectGit/OASystem\\\\pyamf\\\\remoting\\\\gateway\\\\__init__.py", line 513, in callServiceRequest\\n    return service_request(*args)\\n\', \'  File "H:/ProjectGit/OASystem\\\\pyamf\\\\remoting\\\\gateway\\\\__init__.py", line 233, in __call__\\n    return self.service(self.method, args)\\n\', \'  File "H:/ProjectGit/OASystem\\\\pyamf\\\\remoting\\\\gateway\\\\__init__.py", line 133, in __call__\\n    return func(*params)\\n\', \'  File "C:\\\\Python27\\\\lib\\\\site-packages\\\\django\\\\contrib\\\\auth\\\\decorators.py", line 23, in _wrapped_view\\n    return view_func(request, *args, **kwargs)\\n\', \'TypeError: getAllUser() takes exactly 1 argument (2 given)\\n\']' clientId='3148d2ce-cb24-4f6d-9ebc-5ed86323b164' headers={} faultCode='TypeError' timeToLive=None messageId='1e5e1774-075e-4680-a3cc-8c7092f1bcef' faultString=u'getAllUser() takes exactly 1 argument (2 given)' correlationId=u'00918D67-05D1-EB8B-9960-85578789D9CF' />
2013_01_29 16:06:12 :<ErrorMessage  body=None extendedData=['Traceback (most recent call last):\n', '  File "H:/ProjectGit/OASystem\\pyamf\\remoting\\amf3.py", line 188, in __call__\n    return self._getBody(amf_request, ro_request, **kwargs)\n', '  File "H:/ProjectGit/OASystem\\pyamf\\remoting\\amf3.py", line 125, in _getBody\n    return self._processRemotingMessage(amf_request, ro_request, **kwargs)\n', '  File "H:/ProjectGit/OASystem\\pyamf\\remoting\\amf3.py", line 171, in _processRemotingMessage\n    *ro_request.body, **kwargs)\n', '  File "H:/ProjectGit/OASystem\\pyamf\\remoting\\gateway\\__init__.py", line 513, in callServiceRequest\n    return service_request(*args)\n', '  File "H:/ProjectGit/OASystem\\pyamf\\remoting\\gateway\\__init__.py", line 233, in __call__\n    return self.service(self.method, args)\n', '  File "H:/ProjectGit/OASystem\\pyamf\\remoting\\gateway\\__init__.py", line 133, in __call__\n    return func(*params)\n', '  File "C:\\Python27\\lib\\site-packages\\django\\contrib\\auth\\decorators.py", line 23, in _wrapped_view\n    return view_func(request, *args, **kwargs)\n', 'TypeError: getAllUser() takes exactly 1 argument (2 given)\n'] rootCause=TypeError('getAllUser() takes exactly 1 argument (2 given)',) timestamp=1359446772 destination=None faultDetail=u'[\'Traceback (most recent call last):\\n\', \'  File "H:/ProjectGit/OASystem\\\\pyamf\\\\remoting\\\\amf3.py", line 188, in __call__\\n    return self._getBody(amf_request, ro_request, **kwargs)\\n\', \'  File "H:/ProjectGit/OASystem\\\\pyamf\\\\remoting\\\\amf3.py", line 125, in _getBody\\n    return self._processRemotingMessage(amf_request, ro_request, **kwargs)\\n\', \'  File "H:/ProjectGit/OASystem\\\\pyamf\\\\remoting\\\\amf3.py", line 171, in _processRemotingMessage\\n    *ro_request.body, **kwargs)\\n\', \'  File "H:/ProjectGit/OASystem\\\\pyamf\\\\remoting\\\\gateway\\\\__init__.py", line 513, in callServiceRequest\\n    return service_request(*args)\\n\', \'  File "H:/ProjectGit/OASystem\\\\pyamf\\\\remoting\\\\gateway\\\\__init__.py", line 233, in __call__\\n    return self.service(self.method, args)\\n\', \'  File "H:/ProjectGit/OASystem\\\\pyamf\\\\remoting\\\\gateway\\\\__init__.py", line 133, in __call__\\n    return func(*params)\\n\', \'  File "C:\\\\Python27\\\\lib\\\\site-packages\\\\django\\\\contrib\\\\auth\\\\decorators.py", line 23, in _wrapped_view\\n    return view_func(request, *args, **kwargs)\\n\', \'TypeError: getAllUser() takes exactly 1 argument (2 given)\\n\']' clientId='fe70e936-211b-4e22-b903-7a426e5bd687' headers={} faultCode='TypeError' timeToLive=None messageId='89055603-3f0f-45ac-9e64-acbe2f7daae8' faultString=u'getAllUser() takes exactly 1 argument (2 given)' correlationId=u'E29BBC83-6B48-2E3A-0D9D-85578789A3AF' />
2013_01_29 16:06:12 :<ErrorMessage  body=None extendedData=['Traceback (most recent call last):\n', '  File "H:/ProjectGit/OASystem\\pyamf\\remoting\\amf3.py", line 188, in __call__\n    return self._getBody(amf_request, ro_request, **kwargs)\n', '  File "H:/ProjectGit/OASystem\\pyamf\\remoting\\amf3.py", line 125, in _getBody\n    return self._processRemotingMessage(amf_request, ro_request, **kwargs)\n', '  File "H:/ProjectGit/OASystem\\pyamf\\remoting\\amf3.py", line 171, in _processRemotingMessage\n    *ro_request.body, **kwargs)\n', '  File "H:/ProjectGit/OASystem\\pyamf\\remoting\\gateway\\__init__.py", line 513, in callServiceRequest\n    return service_request(*args)\n', '  File "H:/ProjectGit/OASystem\\pyamf\\remoting\\gateway\\__init__.py", line 233, in __call__\n    return self.service(self.method, args)\n', '  File "H:/ProjectGit/OASystem\\pyamf\\remoting\\gateway\\__init__.py", line 133, in __call__\n    return func(*params)\n', '  File "C:\\Python27\\lib\\site-packages\\django\\contrib\\auth\\decorators.py", line 23, in _wrapped_view\n    return view_func(request, *args, **kwargs)\n', 'TypeError: userhaschange() takes exactly 1 argument (2 given)\n'] rootCause=TypeError('userhaschange() takes exactly 1 argument (2 given)',) timestamp=1359446772 destination=None faultDetail=u'[\'Traceback (most recent call last):\\n\', \'  File "H:/ProjectGit/OASystem\\\\pyamf\\\\remoting\\\\amf3.py", line 188, in __call__\\n    return self._getBody(amf_request, ro_request, **kwargs)\\n\', \'  File "H:/ProjectGit/OASystem\\\\pyamf\\\\remoting\\\\amf3.py", line 125, in _getBody\\n    return self._processRemotingMessage(amf_request, ro_request, **kwargs)\\n\', \'  File "H:/ProjectGit/OASystem\\\\pyamf\\\\remoting\\\\amf3.py", line 171, in _processRemotingMessage\\n    *ro_request.body, **kwargs)\\n\', \'  File "H:/ProjectGit/OASystem\\\\pyamf\\\\remoting\\\\gateway\\\\__init__.py", line 513, in callServiceRequest\\n    return service_request(*args)\\n\', \'  File "H:/ProjectGit/OASystem\\\\pyamf\\\\remoting\\\\gateway\\\\__init__.py", line 233, in __call__\\n    return self.service(self.method, args)\\n\', \'  File "H:/ProjectGit/OASystem\\\\pyamf\\\\remoting\\\\gateway\\\\__init__.py", line 133, in __call__\\n    return func(*params)\\n\', \'  File "C:\\\\Python27\\\\lib\\\\site-packages\\\\django\\\\contrib\\\\auth\\\\decorators.py", line 23, in _wrapped_view\\n    return view_func(request, *args, **kwargs)\\n\', \'TypeError: userhaschange() takes exactly 1 argument (2 given)\\n\']' clientId='63c5b4f5-5bbe-47b2-b06f-73fe60199767' headers={} faultCode='TypeError' timeToLive=None messageId='6a8594df-923d-4ec0-9d71-638937c14653' faultString=u'userhaschange() takes exactly 1 argument (2 given)' correlationId=u'61F971E7-DE40-1327-7F5E-85578799B801' />
2013_01_29 16:07:45 :<ErrorMessage  body=None extendedData=['Traceback (most recent call last):\n', '  File "H:/ProjectGit/OASystem\\pyamf\\remoting\\amf3.py", line 188, in __call__\n    return self._getBody(amf_request, ro_request, **kwargs)\n', '  File "H:/ProjectGit/OASystem\\pyamf\\remoting\\amf3.py", line 125, in _getBody\n    return self._processRemotingMessage(amf_request, ro_request, **kwargs)\n', '  File "H:/ProjectGit/OASystem\\pyamf\\remoting\\amf3.py", line 171, in _processRemotingMessage\n    *ro_request.body, **kwargs)\n', '  File "H:/ProjectGit/OASystem\\pyamf\\remoting\\gateway\\__init__.py", line 513, in callServiceRequest\n    return service_request(*args)\n', '  File "H:/ProjectGit/OASystem\\pyamf\\remoting\\gateway\\__init__.py", line 233, in __call__\n    return self.service(self.method, args)\n', '  File "H:/ProjectGit/OASystem\\pyamf\\remoting\\gateway\\__init__.py", line 133, in __call__\n    return func(*params)\n', '  File "C:\\Python27\\lib\\site-packages\\django\\contrib\\auth\\decorators.py", line 23, in _wrapped_view\n    return view_func(request, *args, **kwargs)\n', 'TypeError: getUser() takes exactly 1 argument (2 given)\n'] rootCause=TypeError('getUser() takes exactly 1 argument (2 given)',) timestamp=1359446865 destination=None faultDetail=u'[\'Traceback (most recent call last):\\n\', \'  File "H:/ProjectGit/OASystem\\\\pyamf\\\\remoting\\\\amf3.py", line 188, in __call__\\n    return self._getBody(amf_request, ro_request, **kwargs)\\n\', \'  File "H:/ProjectGit/OASystem\\\\pyamf\\\\remoting\\\\amf3.py", line 125, in _getBody\\n    return self._processRemotingMessage(amf_request, ro_request, **kwargs)\\n\', \'  File "H:/ProjectGit/OASystem\\\\pyamf\\\\remoting\\\\amf3.py", line 171, in _processRemotingMessage\\n    *ro_request.body, **kwargs)\\n\', \'  File "H:/ProjectGit/OASystem\\\\pyamf\\\\remoting\\\\gateway\\\\__init__.py", line 513, in callServiceRequest\\n    return service_request(*args)\\n\', \'  File "H:/ProjectGit/OASystem\\\\pyamf\\\\remoting\\\\gateway\\\\__init__.py", line 233, in __call__\\n    return self.service(self.method, args)\\n\', \'  File "H:/ProjectGit/OASystem\\\\pyamf\\\\remoting\\\\gateway\\\\__init__.py", line 133, in __call__\\n    return func(*params)\\n\', \'  File "C:\\\\Python27\\\\lib\\\\site-packages\\\\django\\\\contrib\\\\auth\\\\decorators.py", line 23, in _wrapped_view\\n    return view_func(request, *args, **kwargs)\\n\', \'TypeError: getUser() takes exactly 1 argument (2 given)\\n\']' clientId='9254d191-40ce-4950-acb9-319704ac4376' headers={} faultCode='TypeError' timeToLive=None messageId='c9462b68-a1b0-42c4-b2af-5020ca6b5e03' faultString=u'getUser() takes exactly 1 argument (2 given)' correlationId=u'67F5FE52-4A68-E58D-2984-8558F3BCB827' />
2013_01_29 16:07:45 :<ErrorMessage  body=None extendedData=['Traceback (most recent call last):\n', '  File "H:/ProjectGit/OASystem\\pyamf\\remoting\\amf3.py", line 188, in __call__\n    return self._getBody(amf_request, ro_request, **kwargs)\n', '  File "H:/ProjectGit/OASystem\\pyamf\\remoting\\amf3.py", line 125, in _getBody\n    return self._processRemotingMessage(amf_request, ro_request, **kwargs)\n', '  File "H:/ProjectGit/OASystem\\pyamf\\remoting\\amf3.py", line 171, in _processRemotingMessage\n    *ro_request.body, **kwargs)\n', '  File "H:/ProjectGit/OASystem\\pyamf\\remoting\\gateway\\__init__.py", line 513, in callServiceRequest\n    return service_request(*args)\n', '  File "H:/ProjectGit/OASystem\\pyamf\\remoting\\gateway\\__init__.py", line 233, in __call__\n    return self.service(self.method, args)\n', '  File "H:/ProjectGit/OASystem\\pyamf\\remoting\\gateway\\__init__.py", line 133, in __call__\n    return func(*params)\n', '  File "C:\\Python27\\lib\\site-packages\\django\\contrib\\auth\\decorators.py", line 23, in _wrapped_view\n    return view_func(request, *args, **kwargs)\n', 'TypeError: getAllUser() takes exactly 1 argument (2 given)\n'] rootCause=TypeError('getAllUser() takes exactly 1 argument (2 given)',) timestamp=1359446865 destination=None faultDetail=u'[\'Traceback (most recent call last):\\n\', \'  File "H:/ProjectGit/OASystem\\\\pyamf\\\\remoting\\\\amf3.py", line 188, in __call__\\n    return self._getBody(amf_request, ro_request, **kwargs)\\n\', \'  File "H:/ProjectGit/OASystem\\\\pyamf\\\\remoting\\\\amf3.py", line 125, in _getBody\\n    return self._processRemotingMessage(amf_request, ro_request, **kwargs)\\n\', \'  File "H:/ProjectGit/OASystem\\\\pyamf\\\\remoting\\\\amf3.py", line 171, in _processRemotingMessage\\n    *ro_request.body, **kwargs)\\n\', \'  File "H:/ProjectGit/OASystem\\\\pyamf\\\\remoting\\\\gateway\\\\__init__.py", line 513, in callServiceRequest\\n    return service_request(*args)\\n\', \'  File "H:/ProjectGit/OASystem\\\\pyamf\\\\remoting\\\\gateway\\\\__init__.py", line 233, in __call__\\n    return self.service(self.method, args)\\n\', \'  File "H:/ProjectGit/OASystem\\\\pyamf\\\\remoting\\\\gateway\\\\__init__.py", line 133, in __call__\\n    return func(*params)\\n\', \'  File "C:\\\\Python27\\\\lib\\\\site-packages\\\\django\\\\contrib\\\\auth\\\\decorators.py", line 23, in _wrapped_view\\n    return view_func(request, *args, **kwargs)\\n\', \'TypeError: getAllUser() takes exactly 1 argument (2 given)\\n\']' clientId='1e766df5-2abb-43b7-b954-d08440364ab0' headers={} faultCode='TypeError' timeToLive=None messageId='bcd3016d-4451-4cbd-9903-f4b862f98119' faultString=u'getAllUser() takes exactly 1 argument (2 given)' correlationId=u'10038D6B-5754-2462-11C4-8558F3BCCC3C' />
2013_01_29 16:07:45 :<ErrorMessage  body=None extendedData=['Traceback (most recent call last):\n', '  File "H:/ProjectGit/OASystem\\pyamf\\remoting\\amf3.py", line 188, in __call__\n    return self._getBody(amf_request, ro_request, **kwargs)\n', '  File "H:/ProjectGit/OASystem\\pyamf\\remoting\\amf3.py", line 125, in _getBody\n    return self._processRemotingMessage(amf_request, ro_request, **kwargs)\n', '  File "H:/ProjectGit/OASystem\\pyamf\\remoting\\amf3.py", line 171, in _processRemotingMessage\n    *ro_request.body, **kwargs)\n', '  File "H:/ProjectGit/OASystem\\pyamf\\remoting\\gateway\\__init__.py", line 513, in callServiceRequest\n    return service_request(*args)\n', '  File "H:/ProjectGit/OASystem\\pyamf\\remoting\\gateway\\__init__.py", line 233, in __call__\n    return self.service(self.method, args)\n', '  File "H:/ProjectGit/OASystem\\pyamf\\remoting\\gateway\\__init__.py", line 133, in __call__\n    return func(*params)\n', '  File "C:\\Python27\\lib\\site-packages\\django\\contrib\\auth\\decorators.py", line 23, in _wrapped_view\n    return view_func(request, *args, **kwargs)\n', 'TypeError: getAllUser() takes exactly 1 argument (2 given)\n'] rootCause=TypeError('getAllUser() takes exactly 1 argument (2 given)',) timestamp=1359446865 destination=None faultDetail=u'[\'Traceback (most recent call last):\\n\', \'  File "H:/ProjectGit/OASystem\\\\pyamf\\\\remoting\\\\amf3.py", line 188, in __call__\\n    return self._getBody(amf_request, ro_request, **kwargs)\\n\', \'  File "H:/ProjectGit/OASystem\\\\pyamf\\\\remoting\\\\amf3.py", line 125, in _getBody\\n    return self._processRemotingMessage(amf_request, ro_request, **kwargs)\\n\', \'  File "H:/ProjectGit/OASystem\\\\pyamf\\\\remoting\\\\amf3.py", line 171, in _processRemotingMessage\\n    *ro_request.body, **kwargs)\\n\', \'  File "H:/ProjectGit/OASystem\\\\pyamf\\\\remoting\\\\gateway\\\\__init__.py", line 513, in callServiceRequest\\n    return service_request(*args)\\n\', \'  File "H:/ProjectGit/OASystem\\\\pyamf\\\\remoting\\\\gateway\\\\__init__.py", line 233, in __call__\\n    return self.service(self.method, args)\\n\', \'  File "H:/ProjectGit/OASystem\\\\pyamf\\\\remoting\\\\gateway\\\\__init__.py", line 133, in __call__\\n    return func(*params)\\n\', \'  File "C:\\\\Python27\\\\lib\\\\site-packages\\\\django\\\\contrib\\\\auth\\\\decorators.py", line 23, in _wrapped_view\\n    return view_func(request, *args, **kwargs)\\n\', \'TypeError: getAllUser() takes exactly 1 argument (2 given)\\n\']' clientId='76ef36e7-d1a5-4b77-b76d-58ede03d6a2a' headers={} faultCode='TypeError' timeToLive=None messageId='529732b7-ee56-4bf6-bbf3-6f1fe1d8972e' faultString=u'getAllUser() takes exactly 1 argument (2 given)' correlationId=u'6AE7A813-B714-B17E-9238-8558F3BC2DB4' />
2013_01_29 16:07:45 :<ErrorMessage  body=None extendedData=['Traceback (most recent call last):\n', '  File "H:/ProjectGit/OASystem\\pyamf\\remoting\\amf3.py", line 188, in __call__\n    return self._getBody(amf_request, ro_request, **kwargs)\n', '  File "H:/ProjectGit/OASystem\\pyamf\\remoting\\amf3.py", line 125, in _getBody\n    return self._processRemotingMessage(amf_request, ro_request, **kwargs)\n', '  File "H:/ProjectGit/OASystem\\pyamf\\remoting\\amf3.py", line 171, in _processRemotingMessage\n    *ro_request.body, **kwargs)\n', '  File "H:/ProjectGit/OASystem\\pyamf\\remoting\\gateway\\__init__.py", line 513, in callServiceRequest\n    return service_request(*args)\n', '  File "H:/ProjectGit/OASystem\\pyamf\\remoting\\gateway\\__init__.py", line 233, in __call__\n    return self.service(self.method, args)\n', '  File "H:/ProjectGit/OASystem\\pyamf\\remoting\\gateway\\__init__.py", line 133, in __call__\n    return func(*params)\n', '  File "C:\\Python27\\lib\\site-packages\\django\\contrib\\auth\\decorators.py", line 23, in _wrapped_view\n    return view_func(request, *args, **kwargs)\n', 'TypeError: userhaschange() takes exactly 1 argument (2 given)\n'] rootCause=TypeError('userhaschange() takes exactly 1 argument (2 given)',) timestamp=1359446865 destination=None faultDetail=u'[\'Traceback (most recent call last):\\n\', \'  File "H:/ProjectGit/OASystem\\\\pyamf\\\\remoting\\\\amf3.py", line 188, in __call__\\n    return self._getBody(amf_request, ro_request, **kwargs)\\n\', \'  File "H:/ProjectGit/OASystem\\\\pyamf\\\\remoting\\\\amf3.py", line 125, in _getBody\\n    return self._processRemotingMessage(amf_request, ro_request, **kwargs)\\n\', \'  File "H:/ProjectGit/OASystem\\\\pyamf\\\\remoting\\\\amf3.py", line 171, in _processRemotingMessage\\n    *ro_request.body, **kwargs)\\n\', \'  File "H:/ProjectGit/OASystem\\\\pyamf\\\\remoting\\\\gateway\\\\__init__.py", line 513, in callServiceRequest\\n    return service_request(*args)\\n\', \'  File "H:/ProjectGit/OASystem\\\\pyamf\\\\remoting\\\\gateway\\\\__init__.py", line 233, in __call__\\n    return self.service(self.method, args)\\n\', \'  File "H:/ProjectGit/OASystem\\\\pyamf\\\\remoting\\\\gateway\\\\__init__.py", line 133, in __call__\\n    return func(*params)\\n\', \'  File "C:\\\\Python27\\\\lib\\\\site-packages\\\\django\\\\contrib\\\\auth\\\\decorators.py", line 23, in _wrapped_view\\n    return view_func(request, *args, **kwargs)\\n\', \'TypeError: userhaschange() takes exactly 1 argument (2 given)\\n\']' clientId='80631012-8d15-44d6-97c0-4b12c6d2ec43' headers={} faultCode='TypeError' timeToLive=None messageId='2901600b-4379-4c3a-8e6b-9c671aa8ce68' faultString=u'userhaschange() takes exactly 1 argument (2 given)' correlationId=u'079A3613-BE07-5E40-F4B8-8558F3BC4BB0' />
2013_01_29 16:08:12 :<ErrorMessage  body=None extendedData=['Traceback (most recent call last):\n', '  File "H:/ProjectGit/OASystem\\pyamf\\remoting\\amf3.py", line 188, in __call__\n    return self._getBody(amf_request, ro_request, **kwargs)\n', '  File "H:/ProjectGit/OASystem\\pyamf\\remoting\\amf3.py", line 125, in _getBody\n    return self._processRemotingMessage(amf_request, ro_request, **kwargs)\n', '  File "H:/ProjectGit/OASystem\\pyamf\\remoting\\amf3.py", line 171, in _processRemotingMessage\n    *ro_request.body, **kwargs)\n', '  File "H:/ProjectGit/OASystem\\pyamf\\remoting\\gateway\\__init__.py", line 513, in callServiceRequest\n    return service_request(*args)\n', '  File "H:/ProjectGit/OASystem\\pyamf\\remoting\\gateway\\__init__.py", line 233, in __call__\n    return self.service(self.method, args)\n', '  File "H:/ProjectGit/OASystem\\pyamf\\remoting\\gateway\\__init__.py", line 133, in __call__\n    return func(*params)\n', '  File "C:\\Python27\\lib\\site-packages\\django\\contrib\\auth\\decorators.py", line 23, in _wrapped_view\n    return view_func(request, *args, **kwargs)\n', 'TypeError: getUser() takes exactly 1 argument (2 given)\n'] rootCause=TypeError('getUser() takes exactly 1 argument (2 given)',) timestamp=1359446892 destination=None faultDetail=u'[\'Traceback (most recent call last):\\n\', \'  File "H:/ProjectGit/OASystem\\\\pyamf\\\\remoting\\\\amf3.py", line 188, in __call__\\n    return self._getBody(amf_request, ro_request, **kwargs)\\n\', \'  File "H:/ProjectGit/OASystem\\\\pyamf\\\\remoting\\\\amf3.py", line 125, in _getBody\\n    return self._processRemotingMessage(amf_request, ro_request, **kwargs)\\n\', \'  File "H:/ProjectGit/OASystem\\\\pyamf\\\\remoting\\\\amf3.py", line 171, in _processRemotingMessage\\n    *ro_request.body, **kwargs)\\n\', \'  File "H:/ProjectGit/OASystem\\\\pyamf\\\\remoting\\\\gateway\\\\__init__.py", line 513, in callServiceRequest\\n    return service_request(*args)\\n\', \'  File "H:/ProjectGit/OASystem\\\\pyamf\\\\remoting\\\\gateway\\\\__init__.py", line 233, in __call__\\n    return self.service(self.method, args)\\n\', \'  File "H:/ProjectGit/OASystem\\\\pyamf\\\\remoting\\\\gateway\\\\__init__.py", line 133, in __call__\\n    return func(*params)\\n\', \'  File "C:\\\\Python27\\\\lib\\\\site-packages\\\\django\\\\contrib\\\\auth\\\\decorators.py", line 23, in _wrapped_view\\n    return view_func(request, *args, **kwargs)\\n\', \'TypeError: getUser() takes exactly 1 argument (2 given)\\n\']' clientId='729c80ad-4c15-4d61-a9be-b65b0404c23b' headers={} faultCode='TypeError' timeToLive=None messageId='e0e18e00-b61b-4c0d-9dff-9af1d39eaf86' faultString=u'getUser() takes exactly 1 argument (2 given)' correlationId=u'F01E1327-49BA-06B8-E6BA-85595DC02271' />
2013_01_29 16:08:12 :<ErrorMessage  body=None extendedData=['Traceback (most recent call last):\n', '  File "H:/ProjectGit/OASystem\\pyamf\\remoting\\amf3.py", line 188, in __call__\n    return self._getBody(amf_request, ro_request, **kwargs)\n', '  File "H:/ProjectGit/OASystem\\pyamf\\remoting\\amf3.py", line 125, in _getBody\n    return self._processRemotingMessage(amf_request, ro_request, **kwargs)\n', '  File "H:/ProjectGit/OASystem\\pyamf\\remoting\\amf3.py", line 171, in _processRemotingMessage\n    *ro_request.body, **kwargs)\n', '  File "H:/ProjectGit/OASystem\\pyamf\\remoting\\gateway\\__init__.py", line 513, in callServiceRequest\n    return service_request(*args)\n', '  File "H:/ProjectGit/OASystem\\pyamf\\remoting\\gateway\\__init__.py", line 233, in __call__\n    return self.service(self.method, args)\n', '  File "H:/ProjectGit/OASystem\\pyamf\\remoting\\gateway\\__init__.py", line 133, in __call__\n    return func(*params)\n', '  File "C:\\Python27\\lib\\site-packages\\django\\contrib\\auth\\decorators.py", line 23, in _wrapped_view\n    return view_func(request, *args, **kwargs)\n', 'TypeError: getAllUser() takes exactly 1 argument (2 given)\n'] rootCause=TypeError('getAllUser() takes exactly 1 argument (2 given)',) timestamp=1359446892 destination=None faultDetail=u'[\'Traceback (most recent call last):\\n\', \'  File "H:/ProjectGit/OASystem\\\\pyamf\\\\remoting\\\\amf3.py", line 188, in __call__\\n    return self._getBody(amf_request, ro_request, **kwargs)\\n\', \'  File "H:/ProjectGit/OASystem\\\\pyamf\\\\remoting\\\\amf3.py", line 125, in _getBody\\n    return self._processRemotingMessage(amf_request, ro_request, **kwargs)\\n\', \'  File "H:/ProjectGit/OASystem\\\\pyamf\\\\remoting\\\\amf3.py", line 171, in _processRemotingMessage\\n    *ro_request.body, **kwargs)\\n\', \'  File "H:/ProjectGit/OASystem\\\\pyamf\\\\remoting\\\\gateway\\\\__init__.py", line 513, in callServiceRequest\\n    return service_request(*args)\\n\', \'  File "H:/ProjectGit/OASystem\\\\pyamf\\\\remoting\\\\gateway\\\\__init__.py", line 233, in __call__\\n    return self.service(self.method, args)\\n\', \'  File "H:/ProjectGit/OASystem\\\\pyamf\\\\remoting\\\\gateway\\\\__init__.py", line 133, in __call__\\n    return func(*params)\\n\', \'  File "C:\\\\Python27\\\\lib\\\\site-packages\\\\django\\\\contrib\\\\auth\\\\decorators.py", line 23, in _wrapped_view\\n    return view_func(request, *args, **kwargs)\\n\', \'TypeError: getAllUser() takes exactly 1 argument (2 given)\\n\']' clientId='c9825bb4-7cf5-4c99-83c7-7863da9b13d3' headers={} faultCode='TypeError' timeToLive=None messageId='4181e4bc-9e83-452b-a169-d637007842d0' faultString=u'getAllUser() takes exactly 1 argument (2 given)' correlationId=u'E9F95ED4-803B-D419-BE29-85595DD0DBC0' />
2013_01_29 16:08:13 :<ErrorMessage  body=None extendedData=['Traceback (most recent call last):\n', '  File "H:/ProjectGit/OASystem\\pyamf\\remoting\\amf3.py", line 188, in __call__\n    return self._getBody(amf_request, ro_request, **kwargs)\n', '  File "H:/ProjectGit/OASystem\\pyamf\\remoting\\amf3.py", line 125, in _getBody\n    return self._processRemotingMessage(amf_request, ro_request, **kwargs)\n', '  File "H:/ProjectGit/OASystem\\pyamf\\remoting\\amf3.py", line 171, in _processRemotingMessage\n    *ro_request.body, **kwargs)\n', '  File "H:/ProjectGit/OASystem\\pyamf\\remoting\\gateway\\__init__.py", line 513, in callServiceRequest\n    return service_request(*args)\n', '  File "H:/ProjectGit/OASystem\\pyamf\\remoting\\gateway\\__init__.py", line 233, in __call__\n    return self.service(self.method, args)\n', '  File "H:/ProjectGit/OASystem\\pyamf\\remoting\\gateway\\__init__.py", line 133, in __call__\n    return func(*params)\n', '  File "C:\\Python27\\lib\\site-packages\\django\\contrib\\auth\\decorators.py", line 23, in _wrapped_view\n    return view_func(request, *args, **kwargs)\n', 'TypeError: getAllUser() takes exactly 1 argument (2 given)\n'] rootCause=TypeError('getAllUser() takes exactly 1 argument (2 given)',) timestamp=1359446893 destination=None faultDetail=u'[\'Traceback (most recent call last):\\n\', \'  File "H:/ProjectGit/OASystem\\\\pyamf\\\\remoting\\\\amf3.py", line 188, in __call__\\n    return self._getBody(amf_request, ro_request, **kwargs)\\n\', \'  File "H:/ProjectGit/OASystem\\\\pyamf\\\\remoting\\\\amf3.py", line 125, in _getBody\\n    return self._processRemotingMessage(amf_request, ro_request, **kwargs)\\n\', \'  File "H:/ProjectGit/OASystem\\\\pyamf\\\\remoting\\\\amf3.py", line 171, in _processRemotingMessage\\n    *ro_request.body, **kwargs)\\n\', \'  File "H:/ProjectGit/OASystem\\\\pyamf\\\\remoting\\\\gateway\\\\__init__.py", line 513, in callServiceRequest\\n    return service_request(*args)\\n\', \'  File "H:/ProjectGit/OASystem\\\\pyamf\\\\remoting\\\\gateway\\\\__init__.py", line 233, in __call__\\n    return self.service(self.method, args)\\n\', \'  File "H:/ProjectGit/OASystem\\\\pyamf\\\\remoting\\\\gateway\\\\__init__.py", line 133, in __call__\\n    return func(*params)\\n\', \'  File "C:\\\\Python27\\\\lib\\\\site-packages\\\\django\\\\contrib\\\\auth\\\\decorators.py", line 23, in _wrapped_view\\n    return view_func(request, *args, **kwargs)\\n\', \'TypeError: getAllUser() takes exactly 1 argument (2 given)\\n\']' clientId='2625a1eb-a366-4d4a-ac43-b705a2f1a3fd' headers={} faultCode='TypeError' timeToLive=None messageId='3387a94e-ba88-42d4-8732-e0f20d3ea157' faultString=u'getAllUser() takes exactly 1 argument (2 given)' correlationId=u'4747F0D1-848C-D66A-FA83-85595DE0DAAC' />
2013_01_29 16:08:13 :<ErrorMessage  body=None extendedData=['Traceback (most recent call last):\n', '  File "H:/ProjectGit/OASystem\\pyamf\\remoting\\amf3.py", line 188, in __call__\n    return self._getBody(amf_request, ro_request, **kwargs)\n', '  File "H:/ProjectGit/OASystem\\pyamf\\remoting\\amf3.py", line 125, in _getBody\n    return self._processRemotingMessage(amf_request, ro_request, **kwargs)\n', '  File "H:/ProjectGit/OASystem\\pyamf\\remoting\\amf3.py", line 171, in _processRemotingMessage\n    *ro_request.body, **kwargs)\n', '  File "H:/ProjectGit/OASystem\\pyamf\\remoting\\gateway\\__init__.py", line 513, in callServiceRequest\n    return service_request(*args)\n', '  File "H:/ProjectGit/OASystem\\pyamf\\remoting\\gateway\\__init__.py", line 233, in __call__\n    return self.service(self.method, args)\n', '  File "H:/ProjectGit/OASystem\\pyamf\\remoting\\gateway\\__init__.py", line 133, in __call__\n    return func(*params)\n', '  File "C:\\Python27\\lib\\site-packages\\django\\contrib\\auth\\decorators.py", line 23, in _wrapped_view\n    return view_func(request, *args, **kwargs)\n', 'TypeError: userhaschange() takes exactly 1 argument (2 given)\n'] rootCause=TypeError('userhaschange() takes exactly 1 argument (2 given)',) timestamp=1359446893 destination=None faultDetail=u'[\'Traceback (most recent call last):\\n\', \'  File "H:/ProjectGit/OASystem\\\\pyamf\\\\remoting\\\\amf3.py", line 188, in __call__\\n    return self._getBody(amf_request, ro_request, **kwargs)\\n\', \'  File "H:/ProjectGit/OASystem\\\\pyamf\\\\remoting\\\\amf3.py", line 125, in _getBody\\n    return self._processRemotingMessage(amf_request, ro_request, **kwargs)\\n\', \'  File "H:/ProjectGit/OASystem\\\\pyamf\\\\remoting\\\\amf3.py", line 171, in _processRemotingMessage\\n    *ro_request.body, **kwargs)\\n\', \'  File "H:/ProjectGit/OASystem\\\\pyamf\\\\remoting\\\\gateway\\\\__init__.py", line 513, in callServiceRequest\\n    return service_request(*args)\\n\', \'  File "H:/ProjectGit/OASystem\\\\pyamf\\\\remoting\\\\gateway\\\\__init__.py", line 233, in __call__\\n    return self.service(self.method, args)\\n\', \'  File "H:/ProjectGit/OASystem\\\\pyamf\\\\remoting\\\\gateway\\\\__init__.py", line 133, in __call__\\n    return func(*params)\\n\', \'  File "C:\\\\Python27\\\\lib\\\\site-packages\\\\django\\\\contrib\\\\auth\\\\decorators.py", line 23, in _wrapped_view\\n    return view_func(request, *args, **kwargs)\\n\', \'TypeError: userhaschange() takes exactly 1 argument (2 given)\\n\']' clientId='503d3a82-ee33-49d9-8091-7c5df421c04b' headers={} faultCode='TypeError' timeToLive=None messageId='20dbe901-8fca-4a16-844f-8b30e034cd35' faultString=u'userhaschange() takes exactly 1 argument (2 given)' correlationId=u'E1A0979D-480F-7C39-F35F-85595DFFD35C' />
2013_01_29 16:08:56 :<ErrorMessage  body=None extendedData=['Traceback (most recent call last):\n', '  File "H:/ProjectGit/OASystem\\pyamf\\remoting\\amf3.py", line 188, in __call__\n    return self._getBody(amf_request, ro_request, **kwargs)\n', '  File "H:/ProjectGit/OASystem\\pyamf\\remoting\\amf3.py", line 125, in _getBody\n    return self._processRemotingMessage(amf_request, ro_request, **kwargs)\n', '  File "H:/ProjectGit/OASystem\\pyamf\\remoting\\amf3.py", line 171, in _processRemotingMessage\n    *ro_request.body, **kwargs)\n', '  File "H:/ProjectGit/OASystem\\pyamf\\remoting\\gateway\\__init__.py", line 513, in callServiceRequest\n    return service_request(*args)\n', '  File "H:/ProjectGit/OASystem\\pyamf\\remoting\\gateway\\__init__.py", line 233, in __call__\n    return self.service(self.method, args)\n', '  File "H:/ProjectGit/OASystem\\pyamf\\remoting\\gateway\\__init__.py", line 133, in __call__\n    return func(*params)\n', '  File "C:\\Python27\\lib\\site-packages\\django\\contrib\\auth\\decorators.py", line 23, in _wrapped_view\n    return view_func(request, *args, **kwargs)\n', 'TypeError: getUser() takes exactly 1 argument (2 given)\n'] rootCause=TypeError('getUser() takes exactly 1 argument (2 given)',) timestamp=1359446936 destination=None faultDetail=u'[\'Traceback (most recent call last):\\n\', \'  File "H:/ProjectGit/OASystem\\\\pyamf\\\\remoting\\\\amf3.py", line 188, in __call__\\n    return self._getBody(amf_request, ro_request, **kwargs)\\n\', \'  File "H:/ProjectGit/OASystem\\\\pyamf\\\\remoting\\\\amf3.py", line 125, in _getBody\\n    return self._processRemotingMessage(amf_request, ro_request, **kwargs)\\n\', \'  File "H:/ProjectGit/OASystem\\\\pyamf\\\\remoting\\\\amf3.py", line 171, in _processRemotingMessage\\n    *ro_request.body, **kwargs)\\n\', \'  File "H:/ProjectGit/OASystem\\\\pyamf\\\\remoting\\\\gateway\\\\__init__.py", line 513, in callServiceRequest\\n    return service_request(*args)\\n\', \'  File "H:/ProjectGit/OASystem\\\\pyamf\\\\remoting\\\\gateway\\\\__init__.py", line 233, in __call__\\n    return self.service(self.method, args)\\n\', \'  File "H:/ProjectGit/OASystem\\\\pyamf\\\\remoting\\\\gateway\\\\__init__.py", line 133, in __call__\\n    return func(*params)\\n\', \'  File "C:\\\\Python27\\\\lib\\\\site-packages\\\\django\\\\contrib\\\\auth\\\\decorators.py", line 23, in _wrapped_view\\n    return view_func(request, *args, **kwargs)\\n\', \'TypeError: getUser() takes exactly 1 argument (2 given)\\n\']' clientId='99d9bad6-5668-4679-8b62-076282736ead' headers={} faultCode='TypeError' timeToLive=None messageId='c02dd9ab-500f-4be3-9bf2-f0cfdf637a2d' faultString=u'getUser() takes exactly 1 argument (2 given)' correlationId=u'02AE96E4-8846-686A-D508-8559F201E3ED' />
2013_01_29 16:08:56 :<ErrorMessage  body=None extendedData=['Traceback (most recent call last):\n', '  File "H:/ProjectGit/OASystem\\pyamf\\remoting\\amf3.py", line 188, in __call__\n    return self._getBody(amf_request, ro_request, **kwargs)\n', '  File "H:/ProjectGit/OASystem\\pyamf\\remoting\\amf3.py", line 125, in _getBody\n    return self._processRemotingMessage(amf_request, ro_request, **kwargs)\n', '  File "H:/ProjectGit/OASystem\\pyamf\\remoting\\amf3.py", line 171, in _processRemotingMessage\n    *ro_request.body, **kwargs)\n', '  File "H:/ProjectGit/OASystem\\pyamf\\remoting\\gateway\\__init__.py", line 513, in callServiceRequest\n    return service_request(*args)\n', '  File "H:/ProjectGit/OASystem\\pyamf\\remoting\\gateway\\__init__.py", line 233, in __call__\n    return self.service(self.method, args)\n', '  File "H:/ProjectGit/OASystem\\pyamf\\remoting\\gateway\\__init__.py", line 133, in __call__\n    return func(*params)\n', '  File "C:\\Python27\\lib\\site-packages\\django\\contrib\\auth\\decorators.py", line 23, in _wrapped_view\n    return view_func(request, *args, **kwargs)\n', 'TypeError: getAllUser() takes exactly 1 argument (2 given)\n'] rootCause=TypeError('getAllUser() takes exactly 1 argument (2 given)',) timestamp=1359446936 destination=None faultDetail=u'[\'Traceback (most recent call last):\\n\', \'  File "H:/ProjectGit/OASystem\\\\pyamf\\\\remoting\\\\amf3.py", line 188, in __call__\\n    return self._getBody(amf_request, ro_request, **kwargs)\\n\', \'  File "H:/ProjectGit/OASystem\\\\pyamf\\\\remoting\\\\amf3.py", line 125, in _getBody\\n    return self._processRemotingMessage(amf_request, ro_request, **kwargs)\\n\', \'  File "H:/ProjectGit/OASystem\\\\pyamf\\\\remoting\\\\amf3.py", line 171, in _processRemotingMessage\\n    *ro_request.body, **kwargs)\\n\', \'  File "H:/ProjectGit/OASystem\\\\pyamf\\\\remoting\\\\gateway\\\\__init__.py", line 513, in callServiceRequest\\n    return service_request(*args)\\n\', \'  File "H:/ProjectGit/OASystem\\\\pyamf\\\\remoting\\\\gateway\\\\__init__.py", line 233, in __call__\\n    return self.service(self.method, args)\\n\', \'  File "H:/ProjectGit/OASystem\\\\pyamf\\\\remoting\\\\gateway\\\\__init__.py", line 133, in __call__\\n    return func(*params)\\n\', \'  File "C:\\\\Python27\\\\lib\\\\site-packages\\\\django\\\\contrib\\\\auth\\\\decorators.py", line 23, in _wrapped_view\\n    return view_func(request, *args, **kwargs)\\n\', \'TypeError: getAllUser() takes exactly 1 argument (2 given)\\n\']' clientId='8bd57541-42d4-4765-8ece-42789487973f' headers={} faultCode='TypeError' timeToLive=None messageId='19124c78-795b-4661-b96d-9eb0ff7c87ed' faultString=u'getAllUser() takes exactly 1 argument (2 given)' correlationId=u'9A073C81-11DE-0026-140C-8559F2110B12' />
2013_01_29 16:08:56 :<ErrorMessage  body=None extendedData=['Traceback (most recent call last):\n', '  File "H:/ProjectGit/OASystem\\pyamf\\remoting\\amf3.py", line 188, in __call__\n    return self._getBody(amf_request, ro_request, **kwargs)\n', '  File "H:/ProjectGit/OASystem\\pyamf\\remoting\\amf3.py", line 125, in _getBody\n    return self._processRemotingMessage(amf_request, ro_request, **kwargs)\n', '  File "H:/ProjectGit/OASystem\\pyamf\\remoting\\amf3.py", line 171, in _processRemotingMessage\n    *ro_request.body, **kwargs)\n', '  File "H:/ProjectGit/OASystem\\pyamf\\remoting\\gateway\\__init__.py", line 513, in callServiceRequest\n    return service_request(*args)\n', '  File "H:/ProjectGit/OASystem\\pyamf\\remoting\\gateway\\__init__.py", line 233, in __call__\n    return self.service(self.method, args)\n', '  File "H:/ProjectGit/OASystem\\pyamf\\remoting\\gateway\\__init__.py", line 133, in __call__\n    return func(*params)\n', '  File "C:\\Python27\\lib\\site-packages\\django\\contrib\\auth\\decorators.py", line 23, in _wrapped_view\n    return view_func(request, *args, **kwargs)\n', 'TypeError: getAllUser() takes exactly 1 argument (2 given)\n'] rootCause=TypeError('getAllUser() takes exactly 1 argument (2 given)',) timestamp=1359446936 destination=None faultDetail=u'[\'Traceback (most recent call last):\\n\', \'  File "H:/ProjectGit/OASystem\\\\pyamf\\\\remoting\\\\amf3.py", line 188, in __call__\\n    return self._getBody(amf_request, ro_request, **kwargs)\\n\', \'  File "H:/ProjectGit/OASystem\\\\pyamf\\\\remoting\\\\amf3.py", line 125, in _getBody\\n    return self._processRemotingMessage(amf_request, ro_request, **kwargs)\\n\', \'  File "H:/ProjectGit/OASystem\\\\pyamf\\\\remoting\\\\amf3.py", line 171, in _processRemotingMessage\\n    *ro_request.body, **kwargs)\\n\', \'  File "H:/ProjectGit/OASystem\\\\pyamf\\\\remoting\\\\gateway\\\\__init__.py", line 513, in callServiceRequest\\n    return service_request(*args)\\n\', \'  File "H:/ProjectGit/OASystem\\\\pyamf\\\\remoting\\\\gateway\\\\__init__.py", line 233, in __call__\\n    return self.service(self.method, args)\\n\', \'  File "H:/ProjectGit/OASystem\\\\pyamf\\\\remoting\\\\gateway\\\\__init__.py", line 133, in __call__\\n    return func(*params)\\n\', \'  File "C:\\\\Python27\\\\lib\\\\site-packages\\\\django\\\\contrib\\\\auth\\\\decorators.py", line 23, in _wrapped_view\\n    return view_func(request, *args, **kwargs)\\n\', \'TypeError: getAllUser() takes exactly 1 argument (2 given)\\n\']' clientId='a3dc4b4b-7116-4135-8da5-65651d3b35cd' headers={} faultCode='TypeError' timeToLive=None messageId='31e794c8-e927-4b47-8cae-e2bb5a01cf1f' faultString=u'getAllUser() takes exactly 1 argument (2 given)' correlationId=u'10E8A67A-9649-C9F9-8497-8559F230F7DE' />
2013_01_29 16:11:11 :<ErrorMessage  body=None extendedData=['Traceback (most recent call last):\n', '  File "H:/ProjectGit/OASystem\\pyamf\\remoting\\amf3.py", line 188, in __call__\n    return self._getBody(amf_request, ro_request, **kwargs)\n', '  File "H:/ProjectGit/OASystem\\pyamf\\remoting\\amf3.py", line 125, in _getBody\n    return self._processRemotingMessage(amf_request, ro_request, **kwargs)\n', '  File "H:/ProjectGit/OASystem\\pyamf\\remoting\\amf3.py", line 171, in _processRemotingMessage\n    *ro_request.body, **kwargs)\n', '  File "H:/ProjectGit/OASystem\\pyamf\\remoting\\gateway\\__init__.py", line 513, in callServiceRequest\n    return service_request(*args)\n', '  File "H:/ProjectGit/OASystem\\pyamf\\remoting\\gateway\\__init__.py", line 233, in __call__\n    return self.service(self.method, args)\n', '  File "H:/ProjectGit/OASystem\\pyamf\\remoting\\gateway\\__init__.py", line 133, in __call__\n    return func(*params)\n', '  File "C:\\Python27\\lib\\site-packages\\django\\contrib\\auth\\decorators.py", line 23, in _wrapped_view\n    return view_func(request, *args, **kwargs)\n', 'TypeError: userhaschange() takes exactly 2 arguments (1 given)\n'] rootCause=TypeError('userhaschange() takes exactly 2 arguments (1 given)',) timestamp=1359447071 destination=None faultDetail=u'[\'Traceback (most recent call last):\\n\', \'  File "H:/ProjectGit/OASystem\\\\pyamf\\\\remoting\\\\amf3.py", line 188, in __call__\\n    return self._getBody(amf_request, ro_request, **kwargs)\\n\', \'  File "H:/ProjectGit/OASystem\\\\pyamf\\\\remoting\\\\amf3.py", line 125, in _getBody\\n    return self._processRemotingMessage(amf_request, ro_request, **kwargs)\\n\', \'  File "H:/ProjectGit/OASystem\\\\pyamf\\\\remoting\\\\amf3.py", line 171, in _processRemotingMessage\\n    *ro_request.body, **kwargs)\\n\', \'  File "H:/ProjectGit/OASystem\\\\pyamf\\\\remoting\\\\gateway\\\\__init__.py", line 513, in callServiceRequest\\n    return service_request(*args)\\n\', \'  File "H:/ProjectGit/OASystem\\\\pyamf\\\\remoting\\\\gateway\\\\__init__.py", line 233, in __call__\\n    return self.service(self.method, args)\\n\', \'  File "H:/ProjectGit/OASystem\\\\pyamf\\\\remoting\\\\gateway\\\\__init__.py", line 133, in __call__\\n    return func(*params)\\n\', \'  File "C:\\\\Python27\\\\lib\\\\site-packages\\\\django\\\\contrib\\\\auth\\\\decorators.py", line 23, in _wrapped_view\\n    return view_func(request, *args, **kwargs)\\n\', \'TypeError: userhaschange() takes exactly 2 arguments (1 given)\\n\']' clientId='937bf181-dd8c-4417-b805-462ebf037920' headers={} faultCode='TypeError' timeToLive=None messageId='0b35c667-2890-476c-a537-d339bfdefc73' faultString=u'userhaschange() takes exactly 2 arguments (1 given)' correlationId=u'EAEB36C7-39CD-6C4A-8F4E-855BD6BFB6BE' />
2013_01_29 16:12:30 :<ErrorMessage  body=None extendedData=['Traceback (most recent call last):\n', '  File "H:/ProjectGit/OASystem\\pyamf\\remoting\\amf3.py", line 188, in __call__\n    return self._getBody(amf_request, ro_request, **kwargs)\n', '  File "H:/ProjectGit/OASystem\\pyamf\\remoting\\amf3.py", line 125, in _getBody\n    return self._processRemotingMessage(amf_request, ro_request, **kwargs)\n', '  File "H:/ProjectGit/OASystem\\pyamf\\remoting\\amf3.py", line 171, in _processRemotingMessage\n    *ro_request.body, **kwargs)\n', '  File "H:/ProjectGit/OASystem\\pyamf\\remoting\\gateway\\__init__.py", line 513, in callServiceRequest\n    return service_request(*args)\n', '  File "H:/ProjectGit/OASystem\\pyamf\\remoting\\gateway\\__init__.py", line 233, in __call__\n    return self.service(self.method, args)\n', '  File "H:/ProjectGit/OASystem\\pyamf\\remoting\\gateway\\__init__.py", line 133, in __call__\n    return func(*params)\n', '  File "C:\\Python27\\lib\\site-packages\\django\\contrib\\auth\\decorators.py", line 23, in _wrapped_view\n    return view_func(request, *args, **kwargs)\n', 'TypeError: userhaschange() takes exactly 1 argument (2 given)\n'] rootCause=TypeError('userhaschange() takes exactly 1 argument (2 given)',) timestamp=1359447150 destination=None faultDetail=u'[\'Traceback (most recent call last):\\n\', \'  File "H:/ProjectGit/OASystem\\\\pyamf\\\\remoting\\\\amf3.py", line 188, in __call__\\n    return self._getBody(amf_request, ro_request, **kwargs)\\n\', \'  File "H:/ProjectGit/OASystem\\\\pyamf\\\\remoting\\\\amf3.py", line 125, in _getBody\\n    return self._processRemotingMessage(amf_request, ro_request, **kwargs)\\n\', \'  File "H:/ProjectGit/OASystem\\\\pyamf\\\\remoting\\\\amf3.py", line 171, in _processRemotingMessage\\n    *ro_request.body, **kwargs)\\n\', \'  File "H:/ProjectGit/OASystem\\\\pyamf\\\\remoting\\\\gateway\\\\__init__.py", line 513, in callServiceRequest\\n    return service_request(*args)\\n\', \'  File "H:/ProjectGit/OASystem\\\\pyamf\\\\remoting\\\\gateway\\\\__init__.py", line 233, in __call__\\n    return self.service(self.method, args)\\n\', \'  File "H:/ProjectGit/OASystem\\\\pyamf\\\\remoting\\\\gateway\\\\__init__.py", line 133, in __call__\\n    return func(*params)\\n\', \'  File "C:\\\\Python27\\\\lib\\\\site-packages\\\\django\\\\contrib\\\\auth\\\\decorators.py", line 23, in _wrapped_view\\n    return view_func(request, *args, **kwargs)\\n\', \'TypeError: userhaschange() takes exactly 1 argument (2 given)\\n\']' clientId='5e78bed9-e889-4ecc-968e-a6d9d4686e3f' headers={} faultCode='TypeError' timeToLive=None messageId='c330c2e3-7157-412e-87f8-5d0c771de752' faultString=u'userhaschange() takes exactly 1 argument (2 given)' correlationId=u'C54D950F-1CDA-C59B-F6B2-855D30B21443' />
2013_01_29 16:15:45 :<ErrorMessage  body=None extendedData=['Traceback (most recent call last):\n', '  File "H:/ProjectGit/OASystem\\pyamf\\remoting\\amf3.py", line 188, in __call__\n    return self._getBody(amf_request, ro_request, **kwargs)\n', '  File "H:/ProjectGit/OASystem\\pyamf\\remoting\\amf3.py", line 125, in _getBody\n    return self._processRemotingMessage(amf_request, ro_request, **kwargs)\n', '  File "H:/ProjectGit/OASystem\\pyamf\\remoting\\amf3.py", line 171, in _processRemotingMessage\n    *ro_request.body, **kwargs)\n', '  File "H:/ProjectGit/OASystem\\pyamf\\remoting\\gateway\\__init__.py", line 513, in callServiceRequest\n    return service_request(*args)\n', '  File "H:/ProjectGit/OASystem\\pyamf\\remoting\\gateway\\__init__.py", line 233, in __call__\n    return self.service(self.method, args)\n', '  File "H:/ProjectGit/OASystem\\pyamf\\remoting\\gateway\\__init__.py", line 133, in __call__\n    return func(*params)\n', '  File "C:\\Python27\\lib\\site-packages\\django\\contrib\\auth\\decorators.py", line 23, in _wrapped_view\n    return view_func(request, *args, **kwargs)\n', 'TypeError: userhaschange() takes exactly 1 argument (2 given)\n'] rootCause=TypeError('userhaschange() takes exactly 1 argument (2 given)',) timestamp=1359447345 destination=None faultDetail=u'[\'Traceback (most recent call last):\\n\', \'  File "H:/ProjectGit/OASystem\\\\pyamf\\\\remoting\\\\amf3.py", line 188, in __call__\\n    return self._getBody(amf_request, ro_request, **kwargs)\\n\', \'  File "H:/ProjectGit/OASystem\\\\pyamf\\\\remoting\\\\amf3.py", line 125, in _getBody\\n    return self._processRemotingMessage(amf_request, ro_request, **kwargs)\\n\', \'  File "H:/ProjectGit/OASystem\\\\pyamf\\\\remoting\\\\amf3.py", line 171, in _processRemotingMessage\\n    *ro_request.body, **kwargs)\\n\', \'  File "H:/ProjectGit/OASystem\\\\pyamf\\\\remoting\\\\gateway\\\\__init__.py", line 513, in callServiceRequest\\n    return service_request(*args)\\n\', \'  File "H:/ProjectGit/OASystem\\\\pyamf\\\\remoting\\\\gateway\\\\__init__.py", line 233, in __call__\\n    return self.service(self.method, args)\\n\', \'  File "H:/ProjectGit/OASystem\\\\pyamf\\\\remoting\\\\gateway\\\\__init__.py", line 133, in __call__\\n    return func(*params)\\n\', \'  File "C:\\\\Python27\\\\lib\\\\site-packages\\\\django\\\\contrib\\\\auth\\\\decorators.py", line 23, in _wrapped_view\\n    return view_func(request, *args, **kwargs)\\n\', \'TypeError: userhaschange() takes exactly 1 argument (2 given)\\n\']' clientId='6da4c1f4-7d19-4a17-b81b-ec15749959f9' headers={} faultCode='TypeError' timeToLive=None messageId='3481e31b-637a-4ab8-aea8-7538d4e0a7c1' faultString=u'userhaschange() takes exactly 1 argument (2 given)' correlationId=u'C0320F4E-6149-840F-5E68-856045B20918' />
